<?xml version="1.0" ?>
<robot name="kuka_arm" xmlns:xacro="http://wiki.ros.org/xacro">

    <xacro:include filename="$(find arm_description)/urdf/constants.xacro" />
    <xacro:include filename="$(find arm_description)/urdf/materials.xacro" />

    <xacro:arg name="with_camera" default="false" />
    <xacro:if value="$(arg with_camera)">
        <xacro:include filename="$(find arm_description)/urdf/camera.xacro" />
    </xacro:if>

    <link name="world" />


    <link name="base_link">

        <visual>
            <origin xyz="0 0 0" rpy="0 0 0" />
            <geometry>
                <mesh filename="package://arm_description/meshes/visual/base_link.stl" />
            </geometry>
            <xacro:material_base_frame />
        </visual>

        <collision>
            <origin xyz="0 0 0" rpy="0 0 0" />
            <geometry>
                <mesh filename="package://arm_description/meshes/collision/base_link.stl" />
            </geometry>
        </collision>

        <inertial>
            <origin xyz="0 0 0" rpy="0 0 0" />
            <mass value="16.8" />
            <inertia ixx="0.312" ixy="-0.000195" ixz="0.0809" iyy="0.411" iyz="0.0000657" izz="0.186" />
        </inertial>

    </link>


    <joint name="world-base_link" type="fixed">
        <origin xyz="0 0 0" rpy="0 0 0" />
        <parent link="world" />
        <child link="base_link" />
    </joint>


    <link name="link_1">

        <visual>
            <origin xyz="0 0 0" rpy="0 0 0" />
            <geometry>
                <mesh filename="package://arm_description/meshes/visual/link_1.stl" />
            </geometry>
            <xacro:material_moving_parts />
        </visual>

        <collision>
            <origin xyz="0 0 0" rpy="0 0 0" />
            <geometry>
                <mesh filename="package://arm_description/meshes/collision/link_1.stl" />
            </geometry>
        </collision>

        <inertial>
            <origin xyz="0 0 0" rpy="0 0 0" />
            <mass value="10.0" />
            <inertia ixx="1.24" ixy="-0.000146" ixz="-0.0353" iyy="1.19" iyz="-0.00761" izz="0.0912" />
        </inertial>

    </link>


    <joint name="q1" type="revolute">
        <origin xyz="0 0 0.400" rpy="0 0 0" />
        <parent link="base_link" />
        <child link="link_1" />
        <axis xyz="0 0 -1" />
        <limit effort="100" lower="${-DEG2RAD * 170}" upper="${DEG2RAD * 170}" velocity="${DEG2RAD * 300}" />
        <dynamics damping="0.0" friction="0.0" />
    </joint>


    <transmission name="tran1">
        <type>transmission_interface/SimpleTransmission</type>
        <joint name="q1">
            <hardwareInterface>hardware_interface/EffortJointInterface</hardwareInterface>
        </joint>
        <actuator name="motor1">
            <hardwareInterface>hardware_interface/EffortJointInterface</hardwareInterface>
            <mechanicalReduction>1</mechanicalReduction>
        </actuator>
    </transmission>


    <link name="link_2">

        <visual>
            <origin xyz="0 0 0" rpy="0 0 0" />
            <geometry>
                <mesh filename="package://arm_description/meshes/visual/link_2.stl" />
            </geometry>
            <xacro:material_moving_parts />
        </visual>

        <collision>
            <origin xyz="0 0 0" rpy="0 0 0" />
            <geometry>
                <mesh filename="package://arm_description/meshes/collision/link_2.stl" />
            </geometry>
        </collision>

        <inertial>
            <origin xyz="0 0 0" rpy="0 0 0" />
            <mass value="16.2" />
            <inertia ixx="7.81" ixy="0.00140" ixz="-0.176" iyy="7.78" iyz="0.0459" izz="0.0767" />
        </inertial>

    </link>


    <joint name="q2" type="revolute">
        <origin xyz="0.025 0 0" rpy="0 0 0" />
        <parent link="link_1" />
        <child link="link_2" />
        <axis xyz="0 1 0" />
        <limit effort="100" lower="${-DEG2RAD * 190}" upper="${DEG2RAD * 45}" velocity="${DEG2RAD * 225}" />
        <dynamics damping="0.0" friction="0.0" />
    </joint>


    <transmission name="tran2">
        <type>transmission_interface/SimpleTransmission</type>
        <joint name="q2">
            <hardwareInterface>hardware_interface/EffortJointInterface</hardwareInterface>
        </joint>
        <actuator name="motor2">
            <hardwareInterface>hardware_interface/EffortJointInterface</hardwareInterface>
            <mechanicalReduction>1</mechanicalReduction>
        </actuator>
    </transmission>


    <link name="link_3">

        <visual>
            <origin xyz="0 0 0" rpy="0 0 0" />
            <geometry>
                <mesh filename="package://arm_description/meshes/visual/link_3.stl" />
            </geometry>
            <xacro:material_moving_parts />
        </visual>

        <collision>
            <origin xyz="0 0 0" rpy="0 0 0" />
            <geometry>
                <mesh filename="package://arm_description/meshes/collision/link_3.stl" />
            </geometry>
        </collision>

        <inertial>
            <origin xyz="0 0 0" rpy="0 0 0" />
            <mass value="4.62" />
            <inertia ixx="4.37" ixy="-0.00000359" ixz="-0.186" iyy="4.38" iyz="-0.000112" izz="0.0236" />
        </inertial>

    </link>


    <joint name="q3" type="revolute">
        <origin xyz="0.560 0 0" rpy="0 0 0" />
        <parent link="link_2" />
        <child link="link_3" />
        <axis xyz="0 1 0" />
        <limit effort="100" lower="${-DEG2RAD * 120}" upper="${DEG2RAD * 156}" velocity="${DEG2RAD * 225}" />
        <dynamics damping="0.0" friction="0.0" />
    </joint>


    <transmission name="tran3">
        <type>transmission_interface/SimpleTransmission</type>
        <joint name="q3">
            <hardwareInterface>hardware_interface/EffortJointInterface</hardwareInterface>
        </joint>
        <actuator name="motor3">
            <hardwareInterface>hardware_interface/EffortJointInterface</hardwareInterface>
            <mechanicalReduction>1</mechanicalReduction>
        </actuator>
    </transmission>


    <link name="link_4">

        <visual>
            <origin xyz="0 0 0" rpy="0 0 0" />
            <geometry>
                <mesh filename="package://arm_description/meshes/visual/link_4.stl" />
            </geometry>
            <xacro:material_moving_parts />
        </visual>

        <collision>
            <origin xyz="0 0 0" rpy="0 0 0" />
            <geometry>
                <mesh filename="package://arm_description/meshes/collision/link_4.stl" />
            </geometry>
        </collision>

        <inertial>
            <origin xyz="0 0 0" rpy="0 0 0" />
            <mass value="6.47" />
            <inertia ixx="6.42" ixy="0.00101" ixz="-2.11" iyy="7.18" iyz="0.00229" izz="0.774" />
        </inertial>

    </link>


    <joint name="q4" type="revolute">
        <origin xyz="0 0 0.035" rpy="0 0 0" />
        <parent link="link_3" />
        <child link="link_4" />
        <axis xyz="-1 0 0" />
        <limit effort="100" lower="${-DEG2RAD * 185}" upper="${DEG2RAD * 185}" velocity="${DEG2RAD * 381}" />
        <dynamics damping="0.0" friction="0.0" />
    </joint>


    <transmission name="tran4">
        <type>transmission_interface/SimpleTransmission</type>
        <joint name="q4">
            <hardwareInterface>hardware_interface/EffortJointInterface</hardwareInterface>
        </joint>
        <actuator name="motor4">
            <hardwareInterface>hardware_interface/EffortJointInterface</hardwareInterface>
            <mechanicalReduction>1</mechanicalReduction>
        </actuator>
    </transmission>


    <link name="link_5">

        <visual>
            <origin xyz="0 0 0" rpy="0 0 0" />
            <geometry>
                <mesh filename="package://arm_description/meshes/visual/link_5.stl" />
            </geometry>
            <xacro:material_moving_parts />
        </visual>

        <collision>
            <origin xyz="0 0 0" rpy="0 0 0" />
            <geometry>
                <mesh filename="package://arm_description/meshes/collision/link_5.stl" />
            </geometry>
        </collision>

        <inertial>
            <origin xyz="0 0 0" rpy="0 0 0" />
            <mass value="0.711" />
            <inertia ixx="0.704" ixy="-0.000729" ixz="-0.393" iyy="0.924" iyz="-0.00135" izz="0.221" />
        </inertial>

    </link>


    <joint name="q5" type="revolute">
        <origin xyz="0.515 0 0" rpy="0 0 0" />
        <parent link="link_4" />
        <child link="link_5" />
        <axis xyz="0 1 0" />
        <limit effort="100" lower="${-DEG2RAD * 120}" upper="${DEG2RAD * 120}" velocity="${DEG2RAD * 311}" />
        <dynamics damping="0.0" friction="0.0" />
    </joint>


    <transmission name="tran5">
        <type>transmission_interface/SimpleTransmission</type>
        <joint name="q5">
            <hardwareInterface>hardware_interface/EffortJointInterface</hardwareInterface>
        </joint>
        <actuator name="motor5">
            <hardwareInterface>hardware_interface/EffortJointInterface</hardwareInterface>
            <mechanicalReduction>1</mechanicalReduction>
        </actuator>
    </transmission>


    <link name="link_6">

        <visual>
            <origin xyz="0 0 0" rpy="0 0 0" />
            <geometry>
                <mesh filename="package://arm_description/meshes/visual/link_6.stl" />
            </geometry>
            <xacro:material_moving_parts />
        </visual>

        <collision>
            <origin xyz="0 0 0" rpy="0 0 0" />
            <geometry>
                <mesh filename="package://arm_description/meshes/collision/link_6.stl" />
            </geometry>
        </collision>

        <inertial>
            <origin xyz="0 0 0" rpy="0 0 0" />
            <mass value="0.0225" />
            <inertia ixx="0.0223" ixy="0.0" ixz="-0.0137" iyy="0.0307" iyz="0.0" izz="0.00844" />
        </inertial>

    </link>


    <joint name="q6" type="revolute">
        <origin xyz="0.080 0 0" rpy="0 0 0" />
        <parent link="link_5" />
        <child link="link_6" />
        <axis xyz="-1 0 0" />
        <limit effort="100" lower="${-DEG2RAD * 350}" upper="${DEG2RAD * 350}" velocity="${DEG2RAD * 492}" />
        <dynamics damping="0.0" friction="0.0" />
    </joint>


    <transmission name="tran6">
        <type>transmission_interface/SimpleTransmission</type>
        <joint name="q6">
            <hardwareInterface>hardware_interface/EffortJointInterface</hardwareInterface>
        </joint>
        <actuator name="motor6">
            <hardwareInterface>hardware_interface/EffortJointInterface</hardwareInterface>
            <mechanicalReduction>1</mechanicalReduction>
        </actuator>
    </transmission>


    <link name="tool" />


    <joint name="link_6-tool" type="fixed">
        <parent link="link_6" />
        <child link="tool" />
        <origin xyz="0 0 0" rpy="0 ${DEG2RAD * 90} 0" />
    </joint>


    <!-- Controllers -->
    <gazebo>
        <plugin name="gazebo_ros_control" filename="libgazebo_ros_control.so">
            <robotNamespace>/kuka_arm</robotNamespace>
            <robotSimType>gazebo_ros_control/DefaultRobotHWSim</robotSimType>
        </plugin>
    </gazebo>

</robot>